Workbook

Sheet Overview
A1: Personal Finance — Overview
A2: Open this tab first. All figures are live formulas against the data sheets.
A4: Current monthly commitments
A5: Active EMIs (incl. insurance) | B5: =SUMIF(EMI!G:G,"Active",EMI!D:D)
A6: Chit monthly | B6: =SUM(Chits!F5:F500)
A7: Combined EMI + Chit / month | B7: =B5+B6
A9: Balances & remaining
A10: Friend ledger balance | B10: =SUM(Transactions!E5:E500)-SUM(Transactions!F5:F500)
A11: School fees remaining | B11: =SUM(School_Fees!I5:I500)
A12: Chit remaining | B12: =SUM(Chits!L5:L500)
A13: Phupa remaining | B13: =SUM(Phupa!D5:D500)-SUM(Phupa!E5:E500)
A14: Debt settlements paid | B14: =SUM(Debt_Settlements!G5:G500)
A16: Monthly mix
A17: Item | B17: Amount
A18: EMIs | B18: =B5
A19: Chits | B19: =B6
A21: Open items to action
A22: School installments still Due/Partial | B22: =COUNTIF(School_Fees!J:J,"Due")+COUNTIF(School_Fees!J:J,"Partial")
A23: Chit installments still Due | B23: =COUNTIF(Chit_Payments!I:I,"Due")
A24: Settlements awaiting closure confirmation | B24: =COUNTIFS(Debt_Settlements!I:I,"Paid",Debt_Settlements!J:J,"To Confirm")
A26: How to use
A27: Enter data only on the dark-blue tabs (School_Fees, EMI, Chits, Chit_Payments, Transactions, Debt_Settlements, Phupa, Loans).
A28: Green tabs are dashboards — do not type transactions there.
A29: Always add a new row; never overwrite a paid installment.

Sheet School_Fees_Dashboard
A1: School Fees Dashboard
A2: Live totals from School_Fees. Use this tab for a quick check.
A4: Total fee (all children) | B4: =SUM(School_Fees!G5:G500)
A5: Total paid | B5: =SUM(School_Fees!H5:H500)
A6: Remaining | B6: =SUM(School_Fees!I5:I500)
A7: Payment progress | B7: =IF(B4=0,0,B5/B4)
A8: Open items (Due/Partial) | B8: =COUNTIF(School_Fees!J5:J500,"Due")+COUNTIF(School_Fees!J5:J500,"Partial")
A10: By child
A11: Child | B11: Due | C11: Paid | D11: Remaining
A12: Daughter | B12: =SUMIF(School_Fees!B:B,A12,School_Fees!G:G) | C12: =SUMIF(School_Fees!B:B,A12,School_Fees!H:H) | D12: =B12-C12
A13: Son | B13: =SUMIF(School_Fees!B:B,A13,School_Fees!G:G) | C13: =SUMIF(School_Fees!B:B,A13,School_Fees!H:H) | D13: =B13-C13
A15: By fee type
A16: Fee_Type | B16: Due | C16: Paid
A17: Term 1 | B17: =SUMIF(School_Fees!D:D,A17,School_Fees!G:G) | C17: =SUMIF(School_Fees!D:D,A17,School_Fees!H:H)
A18: Term 2 | B18: =SUMIF(School_Fees!D:D,A18,School_Fees!G:G) | C18: =SUMIF(School_Fees!D:D,A18,School_Fees!H:H)
A19: Term 3 | B19: =SUMIF(School_Fees!D:D,A19,School_Fees!G:G) | C19: =SUMIF(School_Fees!D:D,A19,School_Fees!H:H)
A20: Books & Uniform | B20: =SUMIF(School_Fees!D:D,A20,School_Fees!G:G) | C20: =SUMIF(School_Fees!D:D,A20,School_Fees!H:H)

Sheet School_Fees
A1: School Fees — transaction log
A2: One row per fee installment. Fill Due_Date / Paid_Date when you have them. Remaining is calculated.
A4: Transaction_ID | B4: Child | C4: Grade | D4: Fee_Type | E4: Due_Date | F4: Paid_Date | G4: Amount_Due | H4: Amount_Paid | I4: Remaining | J4: Status | K4: Notes
A5: SF-001 | B5: Daughter | C5: Grade 5 | D5: Term 1 | G5: 40000 | H5: 40000 | I5: =G5-H5 | J5: Paid | K5: Baseline paid amount
A6: SF-002 | B6: Daughter | C6: Grade 5 | D6: Books & Uniform | G6: 16000 | H6: 16000 | I6: =G6-H6 | J6: Paid | K6: Baseline paid amount
A7: SF-003 | B7: Daughter | C7: Grade 5 | D7: Term 2 | G7: 40000 | H7: 0 | I7: =G7-H7 | J7: Due
A8: SF-004 | B8: Daughter | C8: Grade 5 | D8: Term 3 | G8: 40000 | H8: 0 | I8: =G8-H8 | J8: Due
A9: SF-005 | B9: Son | C9: SKG | D9: Term 1 | G9: 34000 | H9: 10000 | I9: =G9-H9 | J9: Partial | K9: ₹10,000 paid; ₹24,000 remaining
A10: SF-006 | B10: Son | C10: SKG | D10: Books & Uniform | G10: 14000 | H10: 14000 | I10: =G10-H10 | J10: Paid | K10: Baseline paid amount
A11: SF-007 | B11: Son | C11: SKG | D11: Term 2 | G11: 34000 | H11: 0 | I11: =G11-H11 | J11: Due
A12: SF-008 | B12: Son | C12: SKG | D12: Term 3 | G12: 32000 | H12: 0 | I12: =G12-H12 | J12: Due

Sheet EMI_Dashboard
A1: EMI Dashboard
A2: Monthly outflow and mix. Health insurance is included as a recurring item.
A4: Active monthly EMI | B4: =SUMIF(EMI!G:G,"Active",EMI!D:D)
A5: Active EMI count | B5: =COUNTIF(EMI!G:G,"Active")
A6: Known principal (where filled) | B6: =SUM(EMI!I5:I500)
A7: Annual EMI outflow (active × 12) | B7: =B4*12
A9: By lender (active)
A10: Lender | B10: Monthly_EMI
A11: Car EMI | B11: =SUMIFS(EMI!D:D,EMI!C:C,A11,EMI!G:G,"Active")
A12: Direct D. Bajaj | B12: =SUMIFS(EMI!D:D,EMI!C:C,A12,EMI!G:G,"Active")
A13: IDFC First | B13: =SUMIFS(EMI!D:D,EMI!C:C,A13,EMI!G:G,"Active")
A14: New Bike EMI | B14: =SUMIFS(EMI!D:D,EMI!C:C,A14,EMI!G:G,"Active")
A15: New PhonePe Loan | B15: =SUMIFS(EMI!D:D,EMI!C:C,A15,EMI!G:G,"Active")
A16: Pocket4 – Bajaj | B16: =SUMIFS(EMI!D:D,EMI!C:C,A16,EMI!G:G,"Active")
A17: Health insurance | B17: =SUMIFS(EMI!D:D,EMI!C:C,A17,EMI!G:G,"Active")

Sheet EMI
A1: EMI register
A2: One row per active/closed EMI. Do not put totals in this table — see EMI_Dashboard.
A4: EMI_ID | B4: Priority | C4: Lender | D4: Monthly_EMI | E4: Product | F4: Category | G4: Status | H4: Debit_Account | I4: Principal | J4: EMIs_Remaining | K4: Notes
A5: EMI-001 | B5: 1 | C5: Car EMI | D5: 11805 | E5: Car | F5: EMI / Loan | G5: Active | H5: kotak-bharathi
A6: EMI-002 | B6: 2 | C6: Direct D. Bajaj | D6: 6537 | E6: Bajaj P.L | F6: EMI / Loan | G6: Active | H6: kotak-bharathi
A7: EMI-003 | B7: 4 | C7: IDFC First | D7: 4989 | E7: Loan | F7: EMI / Loan | G7: Active | H7: kotak-bharathi
A8: EMI-004 | C8: New Bike EMI | D8: 8394 | E8: New Bike | F8: EMI / Loan | G8: Active | H8: AU-bharathi | I8: 120000
A9: EMI-005 | C9: New PhonePe Loan | D9: 17000 | E9: Phone | F9: EMI / Loan | G9: Active | H9: kotak-bharathi | I9: 400000
A10: EMI-006 | C10: Pocket4 – Bajaj | D10: 12000 | E10: Pocket4 | F10: EMI / Loan | G10: Active | H10: kotak-bharathi | I10: 75000
A11: EMI-007 | C11: Health insurance | D11: 1600 | F11: Insurance | G11: Active

Sheet Chits_Dashboard
A1: Chits Dashboard
A2: Master + installment view. Combined monthly = ₹31,250 while both sets run.
A4: Combined monthly payment | B4: =SUM(Chits!F5:F500)
A5: Total commitment | B5: =SUM(Chits!J5:J500)
A6: Paid to date (from installments) | B6: =SUM(Chit_Payments!H5:H500)
A7: Remaining commitment | B7: =B5-B6
A8: Paid installments | B8: =COUNTIF(Chit_Payments!I:I,"Paid")
A9: Upcoming / due installments | B9: =COUNTIF(Chit_Payments!I:I,"Due")
A11: By chit set
A12: Chit_Set | B12: Monthly | C12: Paid | D12: Remaining
A13: =IF(Chits!B5="","",Chits!B5) | B13: =IF(A13="","",Chits!F5) | C13: =IF(A13="","",Chits!K5) | D13: =IF(A13="","",Chits!L5)
A14: =IF(Chits!B6="","",Chits!B6) | B14: =IF(A14="","",Chits!F6) | C14: =IF(A14="","",Chits!K6) | D14: =IF(A14="","",Chits!L6)

Sheet Chits
A1: Chit master
A2: One row per chit set. Paid_To_Date and Remaining are calculated from Chit_Payments.
A4: Chit_Set_ID | B4: Chit_Set | C4: No_of_Chits | D4: Start_Date | E4: Tenure_Months | F4: Monthly_Payment | G4: Current_Month_No | H4: Current_Month | I4: Amount_Taken | J4: Total_Commitment | K4: Paid_To_Date | L4: Remaining | M4: Remaining_Months | N4: Notes
A5: CHIT-SET-01 | B5: 3 Chits – Not Taken | C5: 3 | D5: 46143 | E5: 16 | F5: 18750 | G5: 5 | H5: 46266 | I5: No | J5: 300000 | K5: =SUMIF(Chit_Payments!B:B,A5,Chit_Payments!H:H) | L5: =J5-K5 | M5: =COUNTIFS(Chit_Payments!B:B,A5,Chit_Payments!I:I,"Due") | N5: 3 chits combined. Chit amount not taken. Sep 2026 paid.
A6: CHIT-SET-02 | B6: 2 Chits – Taken | C6: 2 | D6: 45901 | E6: 16 | F6: 12500 | G6: 13 | H6: 46266 | I6: Yes – Both | J6: 200000 | K6: =SUMIF(Chit_Payments!B:B,A6,Chit_Payments!H:H) | L6: =J6-K6 | M6: =COUNTIFS(Chit_Payments!B:B,A6,Chit_Payments!I:I,"Due") | N6: 2 chits combined. Both chit amounts taken. Sep 2026 paid.

Sheet Chit_Payments
A1: Chit installment log
A2: Merged from former Chit1 Payments + Chit2 Payments. One row per month per set. Do not overwrite old rows.
A4: Payment_ID | B4: Chit_Set_ID | C4: Chit_Set | D4: Month_No | E4: Due_Date | F4: Paid_Date | G4: Expected_Amount | H4: Paid_Amount | I4: Status | J4: Payment_Method | K4: Reference_UTR | L4: Notes
A5: CHIT-SET-02-M01 | B5: CHIT-SET-02 | C5: 2 Chits – Taken | D5: 1 | E5: 45910 | G5: 12500 | H5: 12500 | I5: Paid | L5: Paid; actual paid date to be updated/confirmed.
A6: CHIT-SET-02-M02 | B6: CHIT-SET-02 | C6: 2 Chits – Taken | D6: 2 | E6: 45940 | G6: 12500 | H6: 12500 | I6: Paid | L6: Paid; actual paid date to be updated/confirmed.
A7: CHIT-SET-02-M03 | B7: CHIT-SET-02 | C7: 2 Chits – Taken | D7: 3 | E7: 45971 | G7: 12500 | H7: 12500 | I7: Paid | L7: Paid; actual paid date to be updated/confirmed.
A8: CHIT-SET-02-M04 | B8: CHIT-SET-02 | C8: 2 Chits – Taken | D8: 4 | E8: 46001 | G8: 12500 | H8: 12500 | I8: Paid | L8: Paid; actual paid date to be updated/confirmed.
A9: CHIT-SET-02-M05 | B9: CHIT-SET-02 | C9: 2 Chits – Taken | D9: 5 | E9: 46032 | G9: 12500 | H9: 12500 | I9: Paid | L9: Paid; actual paid date to be updated/confirmed.
A10: CHIT-SET-02-M06 | B10: CHIT-SET-02 | C10: 2 Chits – Taken | D10: 6 | E10: 46063 | G10: 12500 | H10: 12500 | I10: Paid | L10: Paid; actual paid date to be updated/confirmed.
A11: CHIT-SET-02-M07 | B11: CHIT-SET-02 | C11: 2 Chits – Taken | D11: 7 | E11: 46091 | G11: 12500 | H11: 12500 | I11: Paid | L11: Paid; actual paid date to be updated/confirmed.
A12: CHIT-SET-02-M08 | B12: CHIT-SET-02 | C12: 2 Chits – Taken | D12: 8 | E12: 46122 | G12: 12500 | H12: 12500 | I12: Paid | L12: Paid; actual paid date to be updated/confirmed.
A13: CHIT-SET-02-M09 | B13: CHIT-SET-02 | C13: 2 Chits – Taken | D13: 9 | E13: 46152 | G13: 12500 | H13: 12500 | I13: Paid | L13: Paid; actual paid date to be updated/confirmed.
A14: CHIT-SET-02-M10 | B14: CHIT-SET-02 | C14: 2 Chits – Taken | D14: 10 | E14: 46183 | G14: 12500 | H14: 12500 | I14: Paid | L14: Paid; actual paid date to be updated/confirmed.
A15: CHIT-SET-02-M11 | B15: CHIT-SET-02 | C15: 2 Chits – Taken | D15: 11 | E15: 46213 | G15: 12500 | H15: 12500 | I15: Paid | L15: Paid; actual paid date to be updated/confirmed.
A16: CHIT-SET-02-M12 | B16: CHIT-SET-02 | C16: 2 Chits – Taken | D16: 12 | E16: 46244 | G16: 12500 | H16: 12500 | I16: Paid | L16: Paid; actual paid date to be updated/confirmed.
A17: CHIT-SET-02-M13 | B17: CHIT-SET-02 | C17: 2 Chits – Taken | D17: 13 | E17: 46275 | G17: 12500 | H17: 12500 | I17: Paid | L17: Paid; actual paid date to be updated/confirmed.
A18: CHIT-SET-02-M14 | B18: CHIT-SET-02 | C18: 2 Chits – Taken | D18: 14 | I18: Due
A19: CHIT-SET-02-M15 | B19: CHIT-SET-02 | C19: 2 Chits – Taken | D19: 15 | I19: Due
A20: CHIT-SET-02-M16 | B20: CHIT-SET-02 | C20: 2 Chits – Taken | D20: 16 | I20: Due
A21: CHIT-SET-01-M01 | B21: CHIT-SET-01 | C21: 3 Chits – Not Taken | D21: 1 | E21: 46152 | G21: 18750 | H21: 18750 | I21: Paid | L21: Paid; actual paid date to be updated/confirmed.
A22: CHIT-SET-01-M02 | B22: CHIT-SET-01 | C22: 3 Chits – Not Taken | D22: 2 | E22: 46183 | G22: 18750 | H22: 18750 | I22: Paid | L22: Paid; actual paid date to be updated/confirmed.
A23: CHIT-SET-01-M03 | B23: CHIT-SET-01 | C23: 3 Chits – Not Taken | D23: 3 | E23: 46213 | G23: 18750 | H23: 18750 | I23: Paid | L23: Paid; actual paid date to be updated/confirmed.
A24: CHIT-SET-01-M04 | B24: CHIT-SET-01 | C24: 3 Chits – Not Taken | D24: 4 | E24: 46244 | G24: 18750 | H24: 18750 | I24: Paid | L24: Paid; actual paid date to be updated/confirmed.
A25: CHIT-SET-01-M05 | B25: CHIT-SET-01 | C25: 3 Chits – Not Taken | D25: 5 | E25: 46275 | G25: 18750 | H25: 18750 | I25: Paid | L25: Paid; actual paid date to be updated/confirmed.
A26: CHIT-SET-01-M07 | B26: CHIT-SET-01 | C26: 3 Chits – Not Taken | I26: Due
A27: CHIT-SET-01-M08 | B27: CHIT-SET-01 | C27: 3 Chits – Not Taken | I27: Due
A28: CHIT-SET-01-M09 | B28: CHIT-SET-01 | C28: 3 Chits – Not Taken | I28: Due
A29: CHIT-SET-01-M10 | B29: CHIT-SET-01 | C29: 3 Chits – Not Taken | I29: Due
A30: CHIT-SET-01-M11 | B30: CHIT-SET-01 | C30: 3 Chits – Not Taken | I30: Due
A31: CHIT-SET-01-M12 | B31: CHIT-SET-01 | C31: 3 Chits – Not Taken | I31: Due
A32: CHIT-SET-01-M13 | B32: CHIT-SET-01 | C32: 3 Chits – Not Taken | I32: Due
A33: CHIT-SET-01-M14 | B33: CHIT-SET-01 | C33: 3 Chits – Not Taken | I33: Due
A34: CHIT-SET-01-M15 | B34: CHIT-SET-01 | C34: 3 Chits – Not Taken | I34: Due
A35: CHIT-SET-01-M16 | B35: CHIT-SET-01 | C35: 3 Chits – Not Taken | I35: Due
A36: CHIT-SET-01-M17 | B36: CHIT-SET-01 | C36: 3 Chits – Not Taken | I36: Due

Sheet Transactions_Dashboard
A1: Transactions Dashboard
A2: Friend ledger health check.
A4: Total credit received | B4: =SUM(Transactions!E5:E500)
A5: Total debit given | B5: =SUM(Transactions!F5:F500)
A6: Current balance (positive = net still with the other party) | B6: =B4-B5
A7: Transaction count | B7: =COUNTA(Transactions!A5:A500)
A10: Credit vs debit trend charts are on Monthly_Summary (same sheet as the month table).

Sheet Transactions
A1: Friend / money ledger
A2: Credit = money received. Debit = money given. Dates are real date values (month-only entries used 1st of that month).
A4: Transaction_ID | B4: Date | C4: Person | D4: Description | E4: Credit | F4: Debit | G4: Running_Balance | H4: Payment_Method | I4: Reference_UTR | J4: Notes
A5: TXN001 | B5: 44999 | C5: Friend | D5: Initial amount received | E5: 645000 | F5: 0 | G5: =SUM($E$5:E5)-SUM($F$5:F5) | H5: Bank/UPI
A6: TXN002 | B6: 45049 | C6: Friend | D6: Amount given | E6: 0 | F6: 40000 | G6: =SUM($E$5:E6)-SUM($F$5:F6) | H6: Bank/UPI
A7: TXN003 | B7: 45050 | C7: Friend | D7: Amount given | E7: 0 | F7: 30000 | G7: =SUM($E$5:E7)-SUM($F$5:F7) | H7: Bank/UPI
A8: TXN004 | B8: 45121 | C8: Friend | D8: Repayment received | E8: 10000 | F8: 0 | G8: =SUM($E$5:E8)-SUM($F$5:F8) | H8: Bank/UPI
A9: TXN005 | B9: 45139 | C9: Friend | D9: Repayment received | E9: 30000 | F9: 0 | G9: =SUM($E$5:E9)-SUM($F$5:F9) | H9: Bank/UPI
A10: TXN006 | B10: 45139 | C10: Friend | D10: Repayment received | E10: 5000 | F10: 5000 | G10: =SUM($E$5:E10)-SUM($F$5:F10) | H10: Bank/UPI | J10: adjusted amount
A11: TXN007 | B11: 45139 | C11: Friend | D11: Repayment received | E11: 2000 | F11: 2000 | G11: =SUM($E$5:E11)-SUM($F$5:F11) | H11: Bank/UPI | J11: adjusted amount
A12: TXN008 | B12: 45159 | C12: Friend | D12: Repayment received | E12: 5000 | F12: 5000 | G12: =SUM($E$5:E12)-SUM($F$5:F12) | H12: Bank/UPI | J12: adjusted amount
A13: TXN009 | B13: 45175 | C13: Friend | D13: Repayment received | E13: 10000 | F13: 10000 | G13: =SUM($E$5:E13)-SUM($F$5:F13) | H13: Bank/UPI | J13: adjusted amount
A14: TXN010 | B14: 45175 | C14: Friend | D14: Repayment received | E14: 5000 | F14: 5000 | G14: =SUM($E$5:E14)-SUM($F$5:F14) | H14: Bank/UPI | J14: adjusted amount
A15: TXN011 | B15: 45178 | C15: Friend | D15: Repayment received | E15: 15000 | F15: 15000 | G15: =SUM($E$5:E15)-SUM($F$5:F15) | H15: Bank/UPI | J15: adjusted amount
A16: TXN012 | B16: 45200 | C16: Friend | D16: Repayment received | E16: 5000 | F16: 5000 | G16: =SUM($E$5:E16)-SUM($F$5:F16) | H16: Bank/UPI | J16: adjusted amount
A17: TXN013 | B17: 45201 | C17: Friend | D17: Repayment received | E17: 15000 | F17: 15000 | G17: =SUM($E$5:E17)-SUM($F$5:F17) | H17: Bank/UPI | J17: adjusted amount
A18: TXN014 | B18: 45202 | C18: Friend | D18: Repayment received | E18: 8000 | F18: 8000 | G18: =SUM($E$5:E18)-SUM($F$5:F18) | H18: Bank/UPI | J18: adjusted amount
A19: TXN015 | B19: 45203 | C19: Friend | D19: Repayment received | E19: 2000 | F19: 2000 | G19: =SUM($E$5:E19)-SUM($F$5:F19) | H19: Bank/UPI | J19: adjusted amount
A20: TXN016 | B20: 45205 | C20: Friend | D20: Repayment received | E20: 20000 | F20: 20000 | G20: =SUM($E$5:E20)-SUM($F$5:F20) | H20: Bank/UPI | J20: adjusted amount
A21: TXN017 | B21: 45200 | C21: Friend | D21: Repayment received | E21: 1000 | F21: 1000 | G21: =SUM($E$5:E21)-SUM($F$5:F21) | H21: Bank/UPI | J21: adjusted amount
A22: TXN018 | B22: 45220 | C22: Friend | D22: Repayment received | E22: 5000 | F22: 5000 | G22: =SUM($E$5:E22)-SUM($F$5:F22) | H22: Bank/UPI | J22: adjusted amount
A23: TXN019 | B23: 45336 | C23: Friend | D23: Amount given | E23: 0 | F23: 19000 | G23: =SUM($E$5:E23)-SUM($F$5:F23) | H23: Bank/UPI
A24: TXN020 | B24: 45342 | C24: Friend | D24: Repayment received | E24: 500 | F24: 0 | G24: =SUM($E$5:E24)-SUM($F$5:F24) | H24: Bank/UPI
A25: TXN021 | B25: 45352 | C25: Friend | D25: Amount given | E25: 0 | F25: 9500 | G25: =SUM($E$5:E25)-SUM($F$5:F25) | H25: Bank/UPI
A26: TXN022 | B26: 45522 | C26: Friend | D26: Amount given | E26: 0 | F26: 50000 | G26: =SUM($E$5:E26)-SUM($F$5:F26) | H26: Bank/UPI
A27: TXN023 | B27: 45565 | C27: Friend | D27: Amount given | E27: 0 | F27: 50000 | G27: =SUM($E$5:E27)-SUM($F$5:F27) | H27: Bank/UPI
A28: TXN024 | B28: 45595 | C28: Friend | D28: Amount given | E28: 0 | F28: 40000 | G28: =SUM($E$5:E28)-SUM($F$5:F28) | H28: Bank/UPI
A29: TXN025 | B29: 45626 | C29: Friend | D29: Amount given | E29: 0 | F29: 40000 | G29: =SUM($E$5:E29)-SUM($F$5:F29) | H29: Bank/UPI
A30: TXN026 | B30: 45653 | C30: Friend | D30: Amount given | E30: 0 | F30: 40000 | G30: =SUM($E$5:E30)-SUM($F$5:F30) | H30: Bank/UPI
A31: TXN027 | B31: 45698 | C31: Friend | D31: Amount given | E31: 0 | F31: 40000 | G31: =SUM($E$5:E31)-SUM($F$5:F31) | H31: Bank/UPI
A32: TXN028 | B32: 45717 | C32: Friend | D32: Amount given | E32: 0 | F32: 30000 | G32: =SUM($E$5:E32)-SUM($F$5:F32) | H32: Bank/UPI | J32: Approximate date
A33: TXN029 | B33: 45744 | C33: Friend | D33: Amount given | E33: 0 | F33: 30000 | G33: =SUM($E$5:E33)-SUM($F$5:F33) | H33: Bank/UPI
A34: TXN030 | B34: 45808 | C34: Friend | D34: Amount given | E34: 0 | F34: 30000 | G34: =SUM($E$5:E34)-SUM($F$5:F34) | H34: Bank/UPI
A35: TXN031 | B35: 45839 | C35: Friend | D35: Amount given | E35: 0 | F35: 30000 | G35: =SUM($E$5:E35)-SUM($F$5:F35) | H35: Bank/UPI
A36: TXN032 | B36: 45901 | C36: Friend | D36: Amount given | E36: 0 | F36: 30000 | G36: =SUM($E$5:E36)-SUM($F$5:F36) | H36: Bank/UPI | J36: Approximate date
A37: TXN033 | B37: 45933 | C37: Friend | D37: Amount given | E37: 0 | F37: 30000 | G37: =SUM($E$5:E37)-SUM($F$5:F37) | H37: Bank/UPI
A38: TXN034 | B38: 45993 | C38: Friend | D38: Amount given | E38: 0 | F38: 30000 | G38: =SUM($E$5:E38)-SUM($F$5:F38) | H38: Bank/UPI
A39: TXN035 | B39: 46025 | C39: Friend | D39: Amount given | E39: 0 | F39: 30000 | G39: =SUM($E$5:E39)-SUM($F$5:F39) | H39: Bank/UPI
A40: TXN036 | B40: 46083 | C40: Friend | D40: Amount given | E40: 0 | F40: 25000 | G40: =SUM($E$5:E40)-SUM($F$5:F40) | H40: Bank/UPI
A41: TXN037 | B41: 46096 | C41: Bharath + 3 others | D41: Support amount given | E41: 0 | F41: 100000 | G41: =SUM($E$5:E41)-SUM($F$5:F41) | H41: Bank/UPI | J41: Treated as amount given to friend
...

Sheet Monthly_Summary
A1: Monthly summary (from Transactions)
A2: Requires real dates in Transactions!B. Month-only source dates were converted to the 1st of that month.
A4: Month | B4: Total_Credit | C4: Total_Debit | D4: Net | E4: Closing_Balance
A5: 44986 | B5: =SUMIFS(Transactions!$E:$E,Transactions!$B:$B,">="&A5,Transactions!$B:$B,"<"&EDATE(A5,1)) | C5: =SUMIFS(Transactions!$F:$F,Transactions!$B:$B,">="&A5,Transactions!$B:$B,"<"&EDATE(A5,1)) | D5: =B5-C5 | E5: =SUMIFS(Transactions!$E:$E,Transactions!$B:$B,"<"&EDATE(A5,1))-SUMIFS(Transactions!$F:$F,Transactions!$B:$B,"<"&EDATE(A5,1))
A6: 45017 | B6: =SUMIFS(Transactions!$E:$E,Transactions!$B:$B,">="&A6,Transactions!$B:$B,"<"&EDATE(A6,1)) | C6: =SUMIFS(Transactions!$F:$F,Transactions!$B:$B,">="&A6,Transactions!$B:$B,"<"&EDATE(A6,1)) | D6: =B6-C6 | E6: =SUMIFS(Transactions!$E:$E,Transactions!$B:$B,"<"&EDATE(A6,1))-SUMIFS(Transactions!$F:$F,Transactions!$B:$B,"<"&EDATE(A6,1))
A7: 45047 | B7: =SUMIFS(Transactions!$E:$E,Transactions!$B:$B,">="&A7,Transactions!$B:$B,"<"&EDATE(A7,1)) | C7: =SUMIFS(Transactions!$F:$F,Transactions!$B:$B,">="&A7,Transactions!$B:$B,"<"&EDATE(A7,1)) | D7: =B7-C7 | E7: =SUMIFS(Transactions!$E:$E,Transactions!$B:$B,"<"&EDATE(A7,1))-SUMIFS(Transactions!$F:$F,Transactions!$B:$B,"<"&EDATE(A7,1))
A8: 45078 | B8: =SUMIFS(Transactions!$E:$E,Transactions!$B:$B,">="&A8,Transactions!$B:$B,"<"&EDATE(A8,1)) | C8: =SUMIFS(Transactions!$F:$F,Transactions!$B:$B,">="&A8,Transactions!$B:$B,"<"&EDATE(A8,1)) | D8: =B8-C8 | E8: =SUMIFS(Transactions!$E:$E,Transactions!$B:$B,"<"&EDATE(A8,1))-SUMIFS(Transactions!$F:$F,Transactions!$B:$B,"<"&EDATE(A8,1))
A9: 45108 | B9: =SUMIFS(Transactions!$E:$E,Transactions!$B:$B,">="&A9,Transactions!$B:$B,"<"&EDATE(A9,1)) | C9: =SUMIFS(Transactions!$F:$F,Transactions!$B:$B,">="&A9,Transactions!$B:$B,"<"&EDATE(A9,1)) | D9: =B9-C9 | E9: =SUMIFS(Transactions!$E:$E,Transactions!$B:$B,"<"&EDATE(A9,1))-SUMIFS(Transactions!$F:$F,Transactions!$B:$B,"<"&EDATE(A9,1))
A10: 45139 | B10: =SUMIFS(Transactions!$E:$E,Transactions!$B:$B,">="&A10,Transactions!$B:$B,"<"&EDATE(A10,1)) | C10: =SUMIFS(Transactions!$F:$F,Transactions!$B:$B,">="&A10,Transactions!$B:$B,"<"&EDATE(A10,1)) | D10: =B10-C10 | E10: =SUMIFS(Transactions!$E:$E,Transactions!$B:$B,"<"&EDATE(A10,1))-SUMIFS(Transactions!$F:$F,Transactions!$B:$B,"<"&EDATE(A10,1))
A11: 45170 | B11: =SUMIFS(Transactions!$E:$E,Transactions!$B:$B,">="&A11,Transactions!$B:$B,"<"&EDATE(A11,1)) | C11: =SUMIFS(Transactions!$F:$F,Transactions!$B:$B,">="&A11,Transactions!$B:$B,"<"&EDATE(A11,1)) | D11: =B11-C11 | E11: =SUMIFS(Transactions!$E:$E,Transactions!$B:$B,"<"&EDATE(A11,1))-SUMIFS(Transactions!$F:$F,Transactions!$B:$B,"<"&EDATE(A11,1))
A12: 45200 | B12: =SUMIFS(Transactions!$E:$E,Transactions!$B:$B,">="&A12,Transactions!$B:$B,"<"&EDATE(A12,1)) | C12: =SUMIFS(Transactions!$F:$F,Transactions!$B:$B,">="&A12,Transactions!$B:$B,"<"&EDATE(A12,1)) | D12: =B12-C12 | E12: =SUMIFS(Transactions!$E:$E,Transactions!$B:$B,"<"&EDATE(A12,1))-SUMIFS(Transactions!$F:$F,Transactions!$B:$B,"<"&EDATE(A12,1))
A13: 45231 | B13: =SUMIFS(Transactions!$E:$E,Transactions!$B:$B,">="&A13,Transactions!$B:$B,"<"&EDATE(A13,1)) | C13: =SUMIFS(Transactions!$F:$F,Transactions!$B:$B,">="&A13,Transactions!$B:$B,"<"&EDATE(A13,1)) | D13: =B13-C13 | E13: =SUMIFS(Transactions!$E:$E,Transactions!$B:$B,"<"&EDATE(A13,1))-SUMIFS(Transactions!$F:$F,Transactions!$B:$B,"<"&EDATE(A13,1))
A14: 45261 | B14: =SUMIFS(Transactions!$E:$E,Transactions!$B:$B,">="&A14,Transactions!$B:$B,"<"&EDATE(A14,1)) | C14: =SUMIFS(Transactions!$F:$F,Transactions!$B:$B,">="&A14,Transactions!$B:$B,"<"&EDATE(A14,1)) | D14: =B14-C14 | E14: =SUMIFS(Transactions!$E:$E,Transactions!$B:$B,"<"&EDATE(A14,1))-SUMIFS(Transactions!$F:$F,Transactions!$B:$B,"<"&EDATE(A14,1))
A15: 45292 | B15: =SUMIFS(Transactions!$E:$E,Transactions!$B:$B,">="&A15,Transactions!$B:$B,"<"&EDATE(A15,1)) | C15: =SUMIFS(Transactions!$F:$F,Transactions!$B:$B,">="&A15,Transactions!$B:$B,"<"&EDATE(A15,1)) | D15: =B15-C15 | E15: =SUMIFS(Transactions!$E:$E,Transactions!$B:$B,"<"&EDATE(A15,1))-SUMIFS(Transactions!$F:$F,Transactions!$B:$B,"<"&EDATE(A15,1))
A16: 45323 | B16: =SUMIFS(Transactions!$E:$E,Transactions!$B:$B,">="&A16,Transactions!$B:$B,"<"&EDATE(A16,1)) | C16: =SUMIFS(Transactions!$F:$F,Transactions!$B:$B,">="&A16,Transactions!$B:$B,"<"&EDATE(A16,1)) | D16: =B16-C16 | E16: =SUMIFS(Transactions!$E:$E,Transactions!$B:$B,"<"&EDATE(A16,1))-SUMIFS(Transactions!$F:$F,Transactions!$B:$B,"<"&EDATE(A16,1))
... A62: 46722 | B62: =SUMIFS(Transactions!$E:$E,Transactions!$B:$B,">="&A62,Transactions!$B:$B,"<"&EDATE(A62,1)) | C62: =SUMIFS(Transactions!$F:$F,Transactions!$B:$B,">="&A62,Transactions!$B:$B,"<"&EDATE(A62,1)) | D62: =B62-C62 | E62: =SUMIFS(Transactions!$E:$E,Transactions!$B:$B,"<"&EDATE(A62,1))-SUMIFS(Transactions!$F:$F,Transactions!$B:$B,"<"&EDATE(A62,1))

Sheet Debt_Dashboard
A1: Debt Settlements Dashboard
A4: Settlement amount (all) | B4: =SUM(Debt_Settlements!F5:F500)
A5: Paid towards settlements | B5: =SUM(Debt_Settlements!G5:G500)
A6: Unpaid settlement gap | B6: =B4-B5
A7: Paid but closure not confirmed | B7: =COUNTIFS(Debt_Settlements!I5:I500,"Paid",Debt_Settlements!J5:J500,"To Confirm")
A8: Rows still Not Updated | B8: =COUNTIF(Debt_Settlements!I5:I500,"Not Updated")
A10: By lender
A11: Lender | B11: Paid
A12: HDFC Bank | B12: =SUMIF(Debt_Settlements!B:B,A12,Debt_Settlements!G:G)
A13: ICICI Bank | B13: =SUMIF(Debt_Settlements!B:B,A13,Debt_Settlements!G:G)

Sheet Debt_Settlements
A1: Debt settlements
A2: Track settlement vs closure. HDFC items are paid; confirm closure / no-dues. Fill ICICI amounts when known.
A4: Debt_ID | B4: Lender | C4: Account_Ending | D4: Liability_Type | E4: Original_Outstanding | F4: Settlement_Amount | G4: Paid_Amount | H4: Settlement_Date | I4: Payment_Status | J4: Closure_Status | K4: No_Dues_Status | L4: Reference_UTR | M4: Notes
A5: DEBT-001 | B5: HDFC Bank | C5: 5796 | D5: Credit Card | F5: 29000 | G5: 29000 | H5: 46255 | I5: Paid | J5: To Confirm | K5: To Confirm | M5: Settlement paid as agreed
A6: DEBT-002 | B6: HDFC Bank | C6: 8768 | D6: HDFC liability – type to confirm | F6: 46000 | G6: 46000 | H6: 46256 | I6: Paid | J6: To Confirm | K6: To Confirm | M6: Settlement paid; confirm whether this is the Jumbo Loan
A7: DEBT-003 | B7: ICICI Bank | D7: Loan / Credit facility | I7: Not Updated | J7: Not Confirmed | K7: Not Confirmed | M7: Additional ICICI liability; details to be added

Sheet Phupa_Dashboard
A1: Phupa Dashboard
A2: Fixes the old #VALUE! remaining balance (amounts are numbers now).
A4: Total amount due | B4: =SUM(Phupa!D5:D500)
A5: Total received | B5: =SUM(Phupa!E5:E500)
A6: Remaining | B6: =B4-B5
A8: By category
A9: Category | B9: Due | C9: Received
A10: Tractor | B10: =SUMIF(Phupa!C:C,A10,Phupa!D:D) | C10: =SUMIF(Phupa!C:C,A10,Phupa!E:E)
A11: Goats | B11: =SUMIF(Phupa!C:C,A11,Phupa!D:D) | C11: =SUMIF(Phupa!C:C,A11,Phupa!E:E)
A12: Goat kids | B12: =SUMIF(Phupa!C:C,A12,Phupa!D:D) | C12: =SUMIF(Phupa!C:C,A12,Phupa!E:E)
A13: Phupi | B13: =SUMIF(Phupa!C:C,A13,Phupa!D:D) | C13: =SUMIF(Phupa!C:C,A13,Phupa!E:E)
A14: Opening amount already received | B14: =SUMIF(Phupa!C:C,A14,Phupa!D:D) | C14: =SUMIF(Phupa!C:C,A14,Phupa!E:E)

Sheet Phupa
A1: Phupa ledger
A2: Opening ₹7,00,000 received is one row. Add each new receipt as a new row. Remaining is calculated.
A4: Transaction_ID | B4: Date | C4: Category | D4: Amount_Due | E4: Amount_Received | F4: Remaining | G4: Notes
A5: PH-001 | C5: Tractor | D5: 480000 | E5: 0 | F5: =D5-E5 | G5: 20 × ₹24,000
A6: PH-002 | C6: Goats | D6: 110000 | E6: 0 | F6: =D6-E6 | G6: As previously provided
A7: PH-003 | C7: Goat kids | D7: 320000 | E7: 0 | F7: =D7-E7 | G7: 48 × average ₹40,000
A8: PH-004 | C8: Phupi | D8: 100000 | E8: 0 | F8: =D8-E8
A9: PH-005 | C9: Opening amount already received | D9: 0 | E9: 700000 | F9: =D9-E9 | G9: Approx. ₹7,00,000 already received before tracker setup; individual payment dates not available.

Sheet Loans_Dashboard
A1: Loans Dashboard
A2: Master loan contracts only. Monthly bank EMIs are on EMI_Dashboard.
A4: Original principal | B4: =SUM(Loans!G5:G500)
A5: Outstanding principal (where filled) | B5: =SUM(Loans!L5:L500)
A6: Monthly EMI (this sheet) | B6: =SUM(Loans!J5:J500)
A7: Active loans | B7: =COUNTIF(Loans!N:N,"Active")
A9: If a bank EMI is missing here, it is probably only on the EMI sheet — that is OK. Optionally add a matching Loans row later.

Sheet Loans
A1: Loan master
A2: Use this for loan contracts. Use EMI sheet for the monthly installment register (Car, Bajaj, IDFC, Bike, PhonePe, Pocket4).
A4: Loan_ID | B4: Loan_Name | C4: Lender | D4: Loan_Type | E4: Start_Date | F4: End_Date | G4: Original_Principal | H4: Interest_Rate_Pct | I4: Tenure_Months | J4: EMI | K4: EMIs_Paid | L4: Outstanding_Principal | M4: Next_EMI_Date | N4: Status | O4: Notes
A5: LOAN-001 | B5: ravindra_2L | C5: ravindra | D5: Personal Loan | G5: 200000 | H5: 0.02 | J5: 35000 | K5: 0 | N5: Active | O5: Possible EMI ₹35,000 was in Loans!B3 (unlabeled). Confirm whether it belongs in the EMI column.

Sheet Setup
A1: Setup & dropdown lists
A2: Edit lists here. Data sheets use these for Status, Method, and Category.
A5: Status | C5: Payment_Method | E5: Child | G5: Fee_Type | I5: EMI_Status | K5: Closure_Status
A6: Paid | C6: UPI | E6: Daughter | G6: Term 1 | I6: Active | K6: To Confirm
A7: Due | C7: Bank/UPI | E7: Son | G7: Term 2 | I7: Closed | K7: Confirmed
A8: Partial | C8: Bank Transfer | G8: Term 3 | I8: Paused | K8: Not Confirmed
A9: Pending | C9: Cash | G9: Books & Uniform | K9: Closed
A10: Overdue | C10: Auto Debit | G10: Transport
A11: Active | C11: Credit Card | G11: Exam
A12: Closed | G12: Other
A13: Skipped
A14: Not Updated

Sheet How_to_Use
A1: How to maintain this workbook
A4: 1. Overview is the home page. Check it once a month.
A5: 2. Add every new payment as a NEW row on the matching data sheet. Do not overwrite old rows.
A6: 3. Store amounts as numbers. The ₹ format is applied automatically — do not type the ₹ symbol.
A7: 4. Store dates with Excel date picker (or DD-MMM-YYYY). Avoid 'Aug-2026' text if you can use 01-Aug-2026.
A8: 5. School_Fees: remaining = due − paid. Status should be Paid / Partial / Due.
A9: 6. EMI: this is your monthly installment register (Car, Bajaj, IDFC, Bike, PhonePe, Pocket4, insurance). Loans is for contract master data.
A10: 7. Chits: keep two master rows. Log each month in Chit_Payments (both sets live in one table now).
A11: 8. Transactions: Credit = received from friend; Debit = given. Running balance is automatic.
A12: 9. Debt_Settlements: HDFC ₹29,000 + ₹46,000 are paid; still confirm closure / no-dues. Add ICICI figures when known.
A13: 10. Phupa: remaining is now a formula. Add each new receipt as its own row so the ₹7,00,000 opening stays intact.
A14: 11. After adding rows, if a table does not expand, click any cell in the table → Table Design → Resize Table.
A15: 12. Dashboards and Overview recalculate when you open the file in Excel / Excel Online.
